{
 "cells": [
  {
   "cell_type": "code",
   "execution_count": 2,
   "metadata": {},
   "outputs": [
    {
     "name": "stderr",
     "output_type": "stream",
     "text": [
      "2023-04-07 10:42:34.823375: I tensorflow/core/platform/cpu_feature_guard.cc:193] This TensorFlow binary is optimized with oneAPI Deep Neural Network Library (oneDNN) to use the following CPU instructions in performance-critical operations:  SSE4.1 SSE4.2\n",
      "To enable them in other operations, rebuild TensorFlow with the appropriate compiler flags.\n"
     ]
    }
   ],
   "source": [
    "import numpy as np \n",
    "import pandas as pd \n",
    "import matplotlib.pyplot as plt \n",
    "from sklearn.utils import shuffle \n",
    "\n",
    "from keras.models import Model \n",
    "from keras.layers import Input, Embedding, Flatten, Dense, Concatenate\n",
    "from keras.layers import Dropout, BatchNormalization, Activation\n",
    "from keras.regularizers import l2\n",
    "from keras.optimizers import SGD, Adam"
   ]
  },
  {
   "cell_type": "code",
   "execution_count": 3,
   "metadata": {},
   "outputs": [],
   "source": [
    "df = pd.read_csv(\"./data/edited_ratings.csv\")"
   ]
  },
  {
   "cell_type": "code",
   "execution_count": 4,
   "metadata": {},
   "outputs": [
    {
     "name": "stderr",
     "output_type": "stream",
     "text": [
      "2023-04-07 10:42:48.269574: I tensorflow/core/platform/cpu_feature_guard.cc:193] This TensorFlow binary is optimized with oneAPI Deep Neural Network Library (oneDNN) to use the following CPU instructions in performance-critical operations:  SSE4.1 SSE4.2\n",
      "To enable them in other operations, rebuild TensorFlow with the appropriate compiler flags.\n"
     ]
    }
   ],
   "source": [
    "N = df.userId.max() + 1 # number of users \n",
    "M = df.movie_idx.max() + 1 # number of movies \n",
    "\n",
    "# split in train and test \n",
    "df = shuffle(df) \n",
    "cutoff = int(0.8*len(df))\n",
    "df_train = df.iloc[:cutoff] \n",
    "df_test = df.iloc[cutoff:] \n",
    "\n",
    "# init vars \n",
    "K = 10 # latent dimensionality \n",
    "mu = df_train.rating.mean() \n",
    "epoch = 25\n",
    "reg = 0 # regularization penalty\n",
    "\n",
    "# keras model \n",
    "u = Input(shape=(1, ))\n",
    "m = Input(shape=(1, ))\n",
    "u_embedding = Embedding(N, K)(u) # (N, 1, K) \n",
    "m_embedding = Embedding(M, K)(m) # (N, 1, K) \n",
    "u_embedding = Flatten()(u_embedding) # (N, K) \n",
    "m_embedding = Flatten()(m_embedding) # (N, K) \n",
    "x = Concatenate()([u_embedding, m_embedding]) # (N, 2K) \n"
   ]
  },
  {
   "cell_type": "code",
   "execution_count": 5,
   "metadata": {},
   "outputs": [],
   "source": [
    "# the neural network \n",
    "x = Dense(400)(x) \n",
    "x = Activation('relu')(x)\n",
    "x = Dense(1)(x)"
   ]
  },
  {
   "cell_type": "code",
   "execution_count": 6,
   "metadata": {},
   "outputs": [
    {
     "name": "stderr",
     "output_type": "stream",
     "text": [
      "/Users/faa/anaconda3/lib/python3.10/site-packages/keras/optimizers/optimizer_v2/gradient_descent.py:111: UserWarning: The `lr` argument is deprecated, use `learning_rate` instead.\n",
      "  super().__init__(name, **kwargs)\n"
     ]
    }
   ],
   "source": [
    "model = Model(inputs=[u, m], outputs = x) \n",
    "model.compile(\n",
    "    loss= 'mse', \n",
    "    optimizer=SGD(lr=0.01, momentum=0.9), \n",
    "    metrics=['mse']\n",
    ")"
   ]
  },
  {
   "cell_type": "code",
   "execution_count": 7,
   "metadata": {},
   "outputs": [
    {
     "name": "stdout",
     "output_type": "stream",
     "text": [
      "Epoch 1/25\n",
      "  1215/125002 [..............................] - ETA: 2:13 - loss: 1.0618 - mse: 1.0618"
     ]
    },
    {
     "ename": "InvalidArgumentError",
     "evalue": "Graph execution error:\n\nDetected at node 'model/embedding/embedding_lookup' defined at (most recent call last):\n    File \"/Users/faa/anaconda3/lib/python3.10/runpy.py\", line 196, in _run_module_as_main\n      return _run_code(code, main_globals, None,\n    File \"/Users/faa/anaconda3/lib/python3.10/runpy.py\", line 86, in _run_code\n      exec(code, run_globals)\n    File \"/Users/faa/anaconda3/lib/python3.10/site-packages/ipykernel_launcher.py\", line 17, in <module>\n      app.launch_new_instance()\n    File \"/Users/faa/anaconda3/lib/python3.10/site-packages/traitlets/config/application.py\", line 992, in launch_instance\n      app.start()\n    File \"/Users/faa/anaconda3/lib/python3.10/site-packages/ipykernel/kernelapp.py\", line 711, in start\n      self.io_loop.start()\n    File \"/Users/faa/anaconda3/lib/python3.10/site-packages/tornado/platform/asyncio.py\", line 199, in start\n      self.asyncio_loop.run_forever()\n    File \"/Users/faa/anaconda3/lib/python3.10/asyncio/base_events.py\", line 603, in run_forever\n      self._run_once()\n    File \"/Users/faa/anaconda3/lib/python3.10/asyncio/base_events.py\", line 1906, in _run_once\n      handle._run()\n    File \"/Users/faa/anaconda3/lib/python3.10/asyncio/events.py\", line 80, in _run\n      self._context.run(self._callback, *self._args)\n    File \"/Users/faa/anaconda3/lib/python3.10/site-packages/ipykernel/kernelbase.py\", line 510, in dispatch_queue\n      await self.process_one()\n    File \"/Users/faa/anaconda3/lib/python3.10/site-packages/ipykernel/kernelbase.py\", line 499, in process_one\n      await dispatch(*args)\n    File \"/Users/faa/anaconda3/lib/python3.10/site-packages/ipykernel/kernelbase.py\", line 406, in dispatch_shell\n      await result\n    File \"/Users/faa/anaconda3/lib/python3.10/site-packages/ipykernel/kernelbase.py\", line 729, in execute_request\n      reply_content = await reply_content\n    File \"/Users/faa/anaconda3/lib/python3.10/site-packages/ipykernel/ipkernel.py\", line 411, in do_execute\n      res = shell.run_cell(\n    File \"/Users/faa/anaconda3/lib/python3.10/site-packages/ipykernel/zmqshell.py\", line 531, in run_cell\n      return super().run_cell(*args, **kwargs)\n    File \"/Users/faa/anaconda3/lib/python3.10/site-packages/IPython/core/interactiveshell.py\", line 2961, in run_cell\n      result = self._run_cell(\n    File \"/Users/faa/anaconda3/lib/python3.10/site-packages/IPython/core/interactiveshell.py\", line 3016, in _run_cell\n      result = runner(coro)\n    File \"/Users/faa/anaconda3/lib/python3.10/site-packages/IPython/core/async_helpers.py\", line 129, in _pseudo_sync_runner\n      coro.send(None)\n    File \"/Users/faa/anaconda3/lib/python3.10/site-packages/IPython/core/interactiveshell.py\", line 3221, in run_cell_async\n      has_raised = await self.run_ast_nodes(code_ast.body, cell_name,\n    File \"/Users/faa/anaconda3/lib/python3.10/site-packages/IPython/core/interactiveshell.py\", line 3400, in run_ast_nodes\n      if await self.run_code(code, result, async_=asy):\n    File \"/Users/faa/anaconda3/lib/python3.10/site-packages/IPython/core/interactiveshell.py\", line 3460, in run_code\n      exec(code_obj, self.user_global_ns, self.user_ns)\n    File \"/var/folders/lt/2b5gcl810xlf0vx16bv4r5m00000gn/T/ipykernel_64859/2390269064.py\", line 1, in <module>\n      r = model.fit(x = [df_train.userId.values, df_train.movie_idx.values],\n    File \"/Users/faa/anaconda3/lib/python3.10/site-packages/keras/utils/traceback_utils.py\", line 65, in error_handler\n      return fn(*args, **kwargs)\n    File \"/Users/faa/anaconda3/lib/python3.10/site-packages/keras/engine/training.py\", line 1564, in fit\n      tmp_logs = self.train_function(iterator)\n    File \"/Users/faa/anaconda3/lib/python3.10/site-packages/keras/engine/training.py\", line 1160, in train_function\n      return step_function(self, iterator)\n    File \"/Users/faa/anaconda3/lib/python3.10/site-packages/keras/engine/training.py\", line 1146, in step_function\n      outputs = model.distribute_strategy.run(run_step, args=(data,))\n    File \"/Users/faa/anaconda3/lib/python3.10/site-packages/keras/engine/training.py\", line 1135, in run_step\n      outputs = model.train_step(data)\n    File \"/Users/faa/anaconda3/lib/python3.10/site-packages/keras/engine/training.py\", line 993, in train_step\n      y_pred = self(x, training=True)\n    File \"/Users/faa/anaconda3/lib/python3.10/site-packages/keras/utils/traceback_utils.py\", line 65, in error_handler\n      return fn(*args, **kwargs)\n    File \"/Users/faa/anaconda3/lib/python3.10/site-packages/keras/engine/training.py\", line 557, in __call__\n      return super().__call__(*args, **kwargs)\n    File \"/Users/faa/anaconda3/lib/python3.10/site-packages/keras/utils/traceback_utils.py\", line 65, in error_handler\n      return fn(*args, **kwargs)\n    File \"/Users/faa/anaconda3/lib/python3.10/site-packages/keras/engine/base_layer.py\", line 1097, in __call__\n      outputs = call_fn(inputs, *args, **kwargs)\n    File \"/Users/faa/anaconda3/lib/python3.10/site-packages/keras/utils/traceback_utils.py\", line 96, in error_handler\n      return fn(*args, **kwargs)\n    File \"/Users/faa/anaconda3/lib/python3.10/site-packages/keras/engine/functional.py\", line 510, in call\n      return self._run_internal_graph(inputs, training=training, mask=mask)\n    File \"/Users/faa/anaconda3/lib/python3.10/site-packages/keras/engine/functional.py\", line 667, in _run_internal_graph\n      outputs = node.layer(*args, **kwargs)\n    File \"/Users/faa/anaconda3/lib/python3.10/site-packages/keras/utils/traceback_utils.py\", line 65, in error_handler\n      return fn(*args, **kwargs)\n    File \"/Users/faa/anaconda3/lib/python3.10/site-packages/keras/engine/base_layer.py\", line 1097, in __call__\n      outputs = call_fn(inputs, *args, **kwargs)\n    File \"/Users/faa/anaconda3/lib/python3.10/site-packages/keras/utils/traceback_utils.py\", line 96, in error_handler\n      return fn(*args, **kwargs)\n    File \"/Users/faa/anaconda3/lib/python3.10/site-packages/keras/layers/core/embedding.py\", line 208, in call\n      out = tf.nn.embedding_lookup(self.embeddings, inputs)\nNode: 'model/embedding/embedding_lookup'\nindices[36,0] = -1 is not in [0, 138492)\n\t [[{{node model/embedding/embedding_lookup}}]] [Op:__inference_train_function_742]",
     "output_type": "error",
     "traceback": [
      "\u001b[0;31m---------------------------------------------------------------------------\u001b[0m",
      "\u001b[0;31mInvalidArgumentError\u001b[0m                      Traceback (most recent call last)",
      "Cell \u001b[0;32mIn[7], line 1\u001b[0m\n\u001b[0;32m----> 1\u001b[0m r \u001b[39m=\u001b[39m model\u001b[39m.\u001b[39;49mfit(x \u001b[39m=\u001b[39;49m [df_train\u001b[39m.\u001b[39;49muserId\u001b[39m.\u001b[39;49mvalues, df_train\u001b[39m.\u001b[39;49mmovie_idx\u001b[39m.\u001b[39;49mvalues],\n\u001b[1;32m      2\u001b[0m                y\u001b[39m=\u001b[39;49m df_train\u001b[39m.\u001b[39;49mrating\u001b[39m.\u001b[39;49mvalues \u001b[39m-\u001b[39;49m mu,\n\u001b[1;32m      3\u001b[0m                epochs\u001b[39m=\u001b[39;49mepoch, \n\u001b[1;32m      4\u001b[0m                batch_size\u001b[39m=\u001b[39;49m\u001b[39m128\u001b[39;49m, \n\u001b[1;32m      5\u001b[0m                validation_data\u001b[39m=\u001b[39;49m(\n\u001b[1;32m      6\u001b[0m                 [df_test\u001b[39m.\u001b[39;49muserId\u001b[39m.\u001b[39;49mvalues, df_test\u001b[39m.\u001b[39;49mmovie_idx\u001b[39m.\u001b[39;49mvalues], \n\u001b[1;32m      7\u001b[0m                 df_test\u001b[39m.\u001b[39;49mrating\u001b[39m.\u001b[39;49mvalues \u001b[39m-\u001b[39;49m mu \n\u001b[1;32m      8\u001b[0m                ))\n",
      "File \u001b[0;32m~/anaconda3/lib/python3.10/site-packages/keras/utils/traceback_utils.py:70\u001b[0m, in \u001b[0;36mfilter_traceback.<locals>.error_handler\u001b[0;34m(*args, **kwargs)\u001b[0m\n\u001b[1;32m     67\u001b[0m     filtered_tb \u001b[39m=\u001b[39m _process_traceback_frames(e\u001b[39m.\u001b[39m__traceback__)\n\u001b[1;32m     68\u001b[0m     \u001b[39m# To get the full stack trace, call:\u001b[39;00m\n\u001b[1;32m     69\u001b[0m     \u001b[39m# `tf.debugging.disable_traceback_filtering()`\u001b[39;00m\n\u001b[0;32m---> 70\u001b[0m     \u001b[39mraise\u001b[39;00m e\u001b[39m.\u001b[39mwith_traceback(filtered_tb) \u001b[39mfrom\u001b[39;00m \u001b[39mNone\u001b[39m\n\u001b[1;32m     71\u001b[0m \u001b[39mfinally\u001b[39;00m:\n\u001b[1;32m     72\u001b[0m     \u001b[39mdel\u001b[39;00m filtered_tb\n",
      "File \u001b[0;32m~/anaconda3/lib/python3.10/site-packages/tensorflow/python/eager/execute.py:54\u001b[0m, in \u001b[0;36mquick_execute\u001b[0;34m(op_name, num_outputs, inputs, attrs, ctx, name)\u001b[0m\n\u001b[1;32m     52\u001b[0m \u001b[39mtry\u001b[39;00m:\n\u001b[1;32m     53\u001b[0m   ctx\u001b[39m.\u001b[39mensure_initialized()\n\u001b[0;32m---> 54\u001b[0m   tensors \u001b[39m=\u001b[39m pywrap_tfe\u001b[39m.\u001b[39mTFE_Py_Execute(ctx\u001b[39m.\u001b[39m_handle, device_name, op_name,\n\u001b[1;32m     55\u001b[0m                                       inputs, attrs, num_outputs)\n\u001b[1;32m     56\u001b[0m \u001b[39mexcept\u001b[39;00m core\u001b[39m.\u001b[39m_NotOkStatusException \u001b[39mas\u001b[39;00m e:\n\u001b[1;32m     57\u001b[0m   \u001b[39mif\u001b[39;00m name \u001b[39mis\u001b[39;00m \u001b[39mnot\u001b[39;00m \u001b[39mNone\u001b[39;00m:\n",
      "\u001b[0;31mInvalidArgumentError\u001b[0m: Graph execution error:\n\nDetected at node 'model/embedding/embedding_lookup' defined at (most recent call last):\n    File \"/Users/faa/anaconda3/lib/python3.10/runpy.py\", line 196, in _run_module_as_main\n      return _run_code(code, main_globals, None,\n    File \"/Users/faa/anaconda3/lib/python3.10/runpy.py\", line 86, in _run_code\n      exec(code, run_globals)\n    File \"/Users/faa/anaconda3/lib/python3.10/site-packages/ipykernel_launcher.py\", line 17, in <module>\n      app.launch_new_instance()\n    File \"/Users/faa/anaconda3/lib/python3.10/site-packages/traitlets/config/application.py\", line 992, in launch_instance\n      app.start()\n    File \"/Users/faa/anaconda3/lib/python3.10/site-packages/ipykernel/kernelapp.py\", line 711, in start\n      self.io_loop.start()\n    File \"/Users/faa/anaconda3/lib/python3.10/site-packages/tornado/platform/asyncio.py\", line 199, in start\n      self.asyncio_loop.run_forever()\n    File \"/Users/faa/anaconda3/lib/python3.10/asyncio/base_events.py\", line 603, in run_forever\n      self._run_once()\n    File \"/Users/faa/anaconda3/lib/python3.10/asyncio/base_events.py\", line 1906, in _run_once\n      handle._run()\n    File \"/Users/faa/anaconda3/lib/python3.10/asyncio/events.py\", line 80, in _run\n      self._context.run(self._callback, *self._args)\n    File \"/Users/faa/anaconda3/lib/python3.10/site-packages/ipykernel/kernelbase.py\", line 510, in dispatch_queue\n      await self.process_one()\n    File \"/Users/faa/anaconda3/lib/python3.10/site-packages/ipykernel/kernelbase.py\", line 499, in process_one\n      await dispatch(*args)\n    File \"/Users/faa/anaconda3/lib/python3.10/site-packages/ipykernel/kernelbase.py\", line 406, in dispatch_shell\n      await result\n    File \"/Users/faa/anaconda3/lib/python3.10/site-packages/ipykernel/kernelbase.py\", line 729, in execute_request\n      reply_content = await reply_content\n    File \"/Users/faa/anaconda3/lib/python3.10/site-packages/ipykernel/ipkernel.py\", line 411, in do_execute\n      res = shell.run_cell(\n    File \"/Users/faa/anaconda3/lib/python3.10/site-packages/ipykernel/zmqshell.py\", line 531, in run_cell\n      return super().run_cell(*args, **kwargs)\n    File \"/Users/faa/anaconda3/lib/python3.10/site-packages/IPython/core/interactiveshell.py\", line 2961, in run_cell\n      result = self._run_cell(\n    File \"/Users/faa/anaconda3/lib/python3.10/site-packages/IPython/core/interactiveshell.py\", line 3016, in _run_cell\n      result = runner(coro)\n    File \"/Users/faa/anaconda3/lib/python3.10/site-packages/IPython/core/async_helpers.py\", line 129, in _pseudo_sync_runner\n      coro.send(None)\n    File \"/Users/faa/anaconda3/lib/python3.10/site-packages/IPython/core/interactiveshell.py\", line 3221, in run_cell_async\n      has_raised = await self.run_ast_nodes(code_ast.body, cell_name,\n    File \"/Users/faa/anaconda3/lib/python3.10/site-packages/IPython/core/interactiveshell.py\", line 3400, in run_ast_nodes\n      if await self.run_code(code, result, async_=asy):\n    File \"/Users/faa/anaconda3/lib/python3.10/site-packages/IPython/core/interactiveshell.py\", line 3460, in run_code\n      exec(code_obj, self.user_global_ns, self.user_ns)\n    File \"/var/folders/lt/2b5gcl810xlf0vx16bv4r5m00000gn/T/ipykernel_64859/2390269064.py\", line 1, in <module>\n      r = model.fit(x = [df_train.userId.values, df_train.movie_idx.values],\n    File \"/Users/faa/anaconda3/lib/python3.10/site-packages/keras/utils/traceback_utils.py\", line 65, in error_handler\n      return fn(*args, **kwargs)\n    File \"/Users/faa/anaconda3/lib/python3.10/site-packages/keras/engine/training.py\", line 1564, in fit\n      tmp_logs = self.train_function(iterator)\n    File \"/Users/faa/anaconda3/lib/python3.10/site-packages/keras/engine/training.py\", line 1160, in train_function\n      return step_function(self, iterator)\n    File \"/Users/faa/anaconda3/lib/python3.10/site-packages/keras/engine/training.py\", line 1146, in step_function\n      outputs = model.distribute_strategy.run(run_step, args=(data,))\n    File \"/Users/faa/anaconda3/lib/python3.10/site-packages/keras/engine/training.py\", line 1135, in run_step\n      outputs = model.train_step(data)\n    File \"/Users/faa/anaconda3/lib/python3.10/site-packages/keras/engine/training.py\", line 993, in train_step\n      y_pred = self(x, training=True)\n    File \"/Users/faa/anaconda3/lib/python3.10/site-packages/keras/utils/traceback_utils.py\", line 65, in error_handler\n      return fn(*args, **kwargs)\n    File \"/Users/faa/anaconda3/lib/python3.10/site-packages/keras/engine/training.py\", line 557, in __call__\n      return super().__call__(*args, **kwargs)\n    File \"/Users/faa/anaconda3/lib/python3.10/site-packages/keras/utils/traceback_utils.py\", line 65, in error_handler\n      return fn(*args, **kwargs)\n    File \"/Users/faa/anaconda3/lib/python3.10/site-packages/keras/engine/base_layer.py\", line 1097, in __call__\n      outputs = call_fn(inputs, *args, **kwargs)\n    File \"/Users/faa/anaconda3/lib/python3.10/site-packages/keras/utils/traceback_utils.py\", line 96, in error_handler\n      return fn(*args, **kwargs)\n    File \"/Users/faa/anaconda3/lib/python3.10/site-packages/keras/engine/functional.py\", line 510, in call\n      return self._run_internal_graph(inputs, training=training, mask=mask)\n    File \"/Users/faa/anaconda3/lib/python3.10/site-packages/keras/engine/functional.py\", line 667, in _run_internal_graph\n      outputs = node.layer(*args, **kwargs)\n    File \"/Users/faa/anaconda3/lib/python3.10/site-packages/keras/utils/traceback_utils.py\", line 65, in error_handler\n      return fn(*args, **kwargs)\n    File \"/Users/faa/anaconda3/lib/python3.10/site-packages/keras/engine/base_layer.py\", line 1097, in __call__\n      outputs = call_fn(inputs, *args, **kwargs)\n    File \"/Users/faa/anaconda3/lib/python3.10/site-packages/keras/utils/traceback_utils.py\", line 96, in error_handler\n      return fn(*args, **kwargs)\n    File \"/Users/faa/anaconda3/lib/python3.10/site-packages/keras/layers/core/embedding.py\", line 208, in call\n      out = tf.nn.embedding_lookup(self.embeddings, inputs)\nNode: 'model/embedding/embedding_lookup'\nindices[36,0] = -1 is not in [0, 138492)\n\t [[{{node model/embedding/embedding_lookup}}]] [Op:__inference_train_function_742]"
     ]
    }
   ],
   "source": [
    "r = model.fit(x = [df_train.userId.values, df_train.movie_idx.values],\n",
    "               y= df_train.rating.values - mu,\n",
    "               epochs=epoch, \n",
    "               batch_size=128, \n",
    "               validation_data=(\n",
    "                [df_test.userId.values, df_test.movie_idx.values], \n",
    "                df_test.rating.values - mu \n",
    "               ))"
   ]
  },
  {
   "cell_type": "code",
   "execution_count": null,
   "metadata": {},
   "outputs": [],
   "source": [
    "# plot losses \n",
    "plt.plot(r.history['loss'], label=\"train loss\")\n",
    "plt.plot(r.history['val_loss'], label='test loss')\n",
    "plt.legend()\n",
    "plt.show()"
   ]
  },
  {
   "cell_type": "code",
   "execution_count": null,
   "metadata": {},
   "outputs": [],
   "source": [
    "# plot mse \n",
    "plt.plot(r.history['mean_squared_error'], label='train mse')\n",
    "plt.plot(r.history['val_mean_squared_error'], label=\"test mse\")\n",
    "plt.legend()\n",
    "plt.show()"
   ]
  }
 ],
 "metadata": {
  "kernelspec": {
   "display_name": "base",
   "language": "python",
   "name": "python3"
  },
  "language_info": {
   "codemirror_mode": {
    "name": "ipython",
    "version": 3
   },
   "file_extension": ".py",
   "mimetype": "text/x-python",
   "name": "python",
   "nbconvert_exporter": "python",
   "pygments_lexer": "ipython3",
   "version": "3.10.9"
  },
  "orig_nbformat": 4
 },
 "nbformat": 4,
 "nbformat_minor": 2
}
